/data/environments/miniconda3/envs/llm-experience/lib/python3.10/site-packages/transformers/utils/generic.py:441: UserWarning: torch.utils._pytree._register_pytree_node is deprecated. Please use torch.utils._pytree.register_pytree_node instead.
  _torch_pytree._register_pytree_node(
/data/environments/miniconda3/envs/llm-experience/lib/python3.10/site-packages/transformers/utils/generic.py:309: UserWarning: torch.utils._pytree._register_pytree_node is deprecated. Please use torch.utils._pytree.register_pytree_node instead.
  _torch_pytree._register_pytree_node(
/data/environments/miniconda3/envs/llm-experience/lib/python3.10/site-packages/colossalai/pipeline/schedule/_utils.py:19: UserWarning: torch.utils._pytree._register_pytree_node is deprecated. Please use torch.utils._pytree.register_pytree_node instead.
  _register_pytree_node(OrderedDict, _odict_flatten, _odict_unflatten)
/data/environments/miniconda3/envs/llm-experience/lib/python3.10/site-packages/torch/utils/_pytree.py:300: UserWarning: <class 'collections.OrderedDict'> is already registered as pytree node. Overwriting the previous registration.
  warnings.warn(
/data/environments/miniconda3/envs/llm-experience/lib/python3.10/site-packages/colossalai/shardformer/layer/normalization.py:45: UserWarning: Please install apex from source (https://github.com/NVIDIA/apex) to use the fused layernorm kernel
  warnings.warn("Please install apex from source (https://github.com/NVIDIA/apex) to use the fused layernorm kernel")
/data/environments/miniconda3/envs/llm-experience/lib/python3.10/site-packages/transformers/utils/generic.py:309: UserWarning: torch.utils._pytree._register_pytree_node is deprecated. Please use torch.utils._pytree.register_pytree_node instead.
  _torch_pytree._register_pytree_node(
False
Loading checkpoint shards:   0%|          | 0/2 [00:00<?, ?it/s]Loading checkpoint shards:  50%|█████     | 1/2 [00:05<00:05,  5.72s/it]Loading checkpoint shards: 100%|██████████| 2/2 [00:11<00:00,  5.80s/it]Loading checkpoint shards: 100%|██████████| 2/2 [00:11<00:00,  5.79s/it]
Exception in thread Thread-16 (_do_normal_analytics_request):
Traceback (most recent call last):
  File "/data/environments/miniconda3/envs/llm-experience/lib/python3.10/site-packages/httpx/_transports/default.py", line 69, in map_httpcore_exceptions
    yield
  File "/data/environments/miniconda3/envs/llm-experience/lib/python3.10/site-packages/httpx/_transports/default.py", line 233, in handle_request
    resp = self._pool.handle_request(req)
  File "/data/environments/miniconda3/envs/llm-experience/lib/python3.10/site-packages/httpcore/_sync/connection_pool.py", line 216, in handle_request
    raise exc from None
  File "/data/environments/miniconda3/envs/llm-experience/lib/python3.10/site-packages/httpcore/_sync/connection_pool.py", line 196, in handle_request
    response = connection.handle_request(
  File "/data/environments/miniconda3/envs/llm-experience/lib/python3.10/site-packages/httpcore/_sync/connection.py", line 99, in handle_request
    raise exc
  File "/data/environments/miniconda3/envs/llm-experience/lib/python3.10/site-packages/httpcore/_sync/connection.py", line 76, in handle_request
    stream = self._connect(request)
  File "/data/environments/miniconda3/envs/llm-experience/lib/python3.10/site-packages/httpcore/_sync/connection.py", line 154, in _connect
    stream = stream.start_tls(**kwargs)
  File "/data/environments/miniconda3/envs/llm-experience/lib/python3.10/site-packages/httpcore/_backends/sync.py", line 152, in start_tls
    with map_exceptions(exc_map):
  File "/data/environments/miniconda3/envs/llm-experience/lib/python3.10/contextlib.py", line 153, in __exit__
    self.gen.throw(typ, value, traceback)
  File "/data/environments/miniconda3/envs/llm-experience/lib/python3.10/site-packages/httpcore/_exceptions.py", line 14, in map_exceptions
    raise to_exc(exc) from exc
httpcore.ConnectTimeout: _ssl.c:990: The handshake operation timed out

The above exception was the direct cause of the following exception:

Traceback (most recent call last):
  File "/data/environments/miniconda3/envs/llm-experience/lib/python3.10/threading.py", line 1016, in _bootstrap_inner
    self.run()
  File "/data/environments/miniconda3/envs/llm-experience/lib/python3.10/threading.py", line 953, in run
    self._target(*self._args, **self._kwargs)
  File "/data/environments/miniconda3/envs/llm-experience/lib/python3.10/site-packages/gradio/analytics.py", line 70, in _do_normal_analytics_request
    data["ip_address"] = get_local_ip_address()
  File "/data/environments/miniconda3/envs/llm-experience/lib/python3.10/site-packages/gradio/analytics.py", line 131, in get_local_ip_address
    ip_address = httpx.get(
  File "/data/environments/miniconda3/envs/llm-experience/lib/python3.10/site-packages/httpx/_api.py", line 198, in get
    return request(
  File "/data/environments/miniconda3/envs/llm-experience/lib/python3.10/site-packages/httpx/_api.py", line 106, in request
    return client.request(
  File "/data/environments/miniconda3/envs/llm-experience/lib/python3.10/site-packages/httpx/_client.py", line 827, in request
    return self.send(request, auth=auth, follow_redirects=follow_redirects)
  File "/data/environments/miniconda3/envs/llm-experience/lib/python3.10/site-packages/httpx/_client.py", line 914, in send
    response = self._send_handling_auth(
  File "/data/environments/miniconda3/envs/llm-experience/lib/python3.10/site-packages/httpx/_client.py", line 942, in _send_handling_auth
    response = self._send_handling_redirects(
  File "/data/environments/miniconda3/envs/llm-experience/lib/python3.10/site-packages/httpx/_client.py", line 979, in _send_handling_redirects
    response = self._send_single_request(request)
  File "/data/environments/miniconda3/envs/llm-experience/lib/python3.10/site-packages/httpx/_client.py", line 1015, in _send_single_request
    response = transport.handle_request(request)
  File "/data/environments/miniconda3/envs/llm-experience/lib/python3.10/site-packages/httpx/_transports/default.py", line 232, in handle_request
    with map_httpcore_exceptions():
  File "/data/environments/miniconda3/envs/llm-experience/lib/python3.10/contextlib.py", line 153, in __exit__
    self.gen.throw(typ, value, traceback)
  File "/data/environments/miniconda3/envs/llm-experience/lib/python3.10/site-packages/httpx/_transports/default.py", line 86, in map_httpcore_exceptions
    raise mapped_exc(message) from exc
httpx.ConnectTimeout: _ssl.c:990: The handshake operation timed out
